[2021-03-04 21:33:53,183] {taskinstance.py:670} INFO - Dependencies all met for <TaskInstance: clean_data.merge_data 2021-03-04T21:27:01.333591+00:00 [queued]>
[2021-03-04 21:33:53,213] {taskinstance.py:670} INFO - Dependencies all met for <TaskInstance: clean_data.merge_data 2021-03-04T21:27:01.333591+00:00 [queued]>
[2021-03-04 21:33:53,214] {taskinstance.py:880} INFO - 
--------------------------------------------------------------------------------
[2021-03-04 21:33:53,214] {taskinstance.py:881} INFO - Starting attempt 2 of 2
[2021-03-04 21:33:53,215] {taskinstance.py:882} INFO - 
--------------------------------------------------------------------------------
[2021-03-04 21:33:53,251] {taskinstance.py:901} INFO - Executing <Task(PythonOperator): merge_data> on 2021-03-04T21:27:01.333591+00:00
[2021-03-04 21:33:53,255] {standard_task_runner.py:54} INFO - Started process 6861 to run task
[2021-03-04 21:33:53,281] {standard_task_runner.py:77} INFO - Running: ['airflow', 'run', 'clean_data', 'merge_data', '2021-03-04T21:27:01.333591+00:00', '--job_id', '88', '--pool', 'default_pool', '--raw', '-sd', 'DAGS_FOLDER/data_clean.py', '--cfg_path', '/tmp/tmpy_iu_bhb']
[2021-03-04 21:33:53,284] {standard_task_runner.py:78} INFO - Job 88: Subtask merge_data
[2021-03-04 21:33:53,342] {logging_mixin.py:112} INFO - Running %s on host %s <TaskInstance: clean_data.merge_data 2021-03-04T21:27:01.333591+00:00 [running]> 6623e80cd770
[2021-03-04 21:33:53,373] {taskinstance.py:1150} ERROR - name 'con' is not defined
Traceback (most recent call last):
  File "/home/airflow/.local/lib/python3.6/site-packages/airflow/models/taskinstance.py", line 984, in _run_raw_task
    result = task_copy.execute(context=context)
  File "/home/airflow/.local/lib/python3.6/site-packages/airflow/operators/python_operator.py", line 113, in execute
    return_value = self.execute_callable()
  File "/home/airflow/.local/lib/python3.6/site-packages/airflow/operators/python_operator.py", line 118, in execute_callable
    return self.python_callable(*self.op_args, **self.op_kwargs)
  File "/opt/airflow/dags/data_clean.py", line 152, in merge_data
    df1 = pd.read_sql(f"select * from clean_search_result_interaction", con)
NameError: name 'con' is not defined
[2021-03-04 21:33:53,378] {taskinstance.py:1194} INFO - Marking task as FAILED. dag_id=clean_data, task_id=merge_data, execution_date=20210304T212701, start_date=20210304T213353, end_date=20210304T213353
[2021-03-04 21:33:58,164] {local_task_job.py:102} INFO - Task exited with return code 1
