[2021-03-04 20:47:42,184] {taskinstance.py:670} INFO - Dependencies all met for <TaskInstance: clean_data.clean_data_search_result_interaction 2021-03-04T20:47:02.270488+00:00 [queued]>
[2021-03-04 20:47:42,226] {taskinstance.py:670} INFO - Dependencies all met for <TaskInstance: clean_data.clean_data_search_result_interaction 2021-03-04T20:47:02.270488+00:00 [queued]>
[2021-03-04 20:47:42,227] {taskinstance.py:880} INFO - 
--------------------------------------------------------------------------------
[2021-03-04 20:47:42,228] {taskinstance.py:881} INFO - Starting attempt 1 of 2
[2021-03-04 20:47:42,228] {taskinstance.py:882} INFO - 
--------------------------------------------------------------------------------
[2021-03-04 20:47:42,280] {taskinstance.py:901} INFO - Executing <Task(PythonOperator): clean_data_search_result_interaction> on 2021-03-04T20:47:02.270488+00:00
[2021-03-04 20:47:42,285] {standard_task_runner.py:54} INFO - Started process 5528 to run task
[2021-03-04 20:47:42,323] {standard_task_runner.py:77} INFO - Running: ['airflow', 'run', 'clean_data', 'clean_data_search_result_interaction', '2021-03-04T20:47:02.270488+00:00', '--job_id', '57', '--pool', 'default_pool', '--raw', '-sd', 'DAGS_FOLDER/data_clean.py', '--cfg_path', '/tmp/tmpid7lsyuf']
[2021-03-04 20:47:42,327] {standard_task_runner.py:78} INFO - Job 57: Subtask clean_data_search_result_interaction
[2021-03-04 20:47:42,423] {logging_mixin.py:112} INFO - Running %s on host %s <TaskInstance: clean_data.clean_data_search_result_interaction 2021-03-04T20:47:02.270488+00:00 [running]> 6623e80cd770
[2021-03-04 20:47:42,621] {logging_mixin.py:112} INFO - (2225, 4)
[2021-03-04 20:47:42,622] {logging_mixin.py:112} WARNING - --- Logging error ---
[2021-03-04 20:47:42,624] {logging_mixin.py:112} WARNING - Traceback (most recent call last):
[2021-03-04 20:47:42,624] {logging_mixin.py:112} WARNING -   File "/usr/local/lib/python3.6/logging/__init__.py", line 994, in emit
    msg = self.format(record)
[2021-03-04 20:47:42,625] {logging_mixin.py:112} WARNING -   File "/usr/local/lib/python3.6/logging/__init__.py", line 840, in format
    return fmt.format(record)
[2021-03-04 20:47:42,625] {logging_mixin.py:112} WARNING -   File "/usr/local/lib/python3.6/logging/__init__.py", line 577, in format
    record.message = record.getMessage()
[2021-03-04 20:47:42,626] {logging_mixin.py:112} WARNING -   File "/usr/local/lib/python3.6/logging/__init__.py", line 338, in getMessage
    msg = msg % self.args
[2021-03-04 20:47:42,626] {logging_mixin.py:112} WARNING - TypeError: not all arguments converted during string formatting
[2021-03-04 20:47:42,627] {logging_mixin.py:112} WARNING - Call stack:
[2021-03-04 20:47:42,643] {logging_mixin.py:112} WARNING -   File "/home/airflow/.local/bin/airflow", line 37, in <module>
    args.func(args)
[2021-03-04 20:47:42,644] {logging_mixin.py:112} WARNING -   File "/home/airflow/.local/lib/python3.6/site-packages/airflow/utils/cli.py", line 76, in wrapper
    return f(*args, **kwargs)
[2021-03-04 20:47:42,645] {logging_mixin.py:112} WARNING -   File "/home/airflow/.local/lib/python3.6/site-packages/airflow/bin/cli.py", line 579, in run
    _run(args, dag, ti)
[2021-03-04 20:47:42,647] {logging_mixin.py:112} WARNING -   File "/home/airflow/.local/lib/python3.6/site-packages/airflow/bin/cli.py", line 475, in _run
    run_job.run()
[2021-03-04 20:47:42,648] {logging_mixin.py:112} WARNING -   File "/home/airflow/.local/lib/python3.6/site-packages/airflow/jobs/base_job.py", line 218, in run
    self._execute()
[2021-03-04 20:47:42,648] {logging_mixin.py:112} WARNING -   File "/home/airflow/.local/lib/python3.6/site-packages/airflow/jobs/local_task_job.py", line 94, in _execute
    self.task_runner.start()
[2021-03-04 20:47:42,650] {logging_mixin.py:112} WARNING -   File "/home/airflow/.local/lib/python3.6/site-packages/airflow/task/task_runner/standard_task_runner.py", line 43, in start
    self.process = self._start_by_fork()
[2021-03-04 20:47:42,651] {logging_mixin.py:112} WARNING -   File "/home/airflow/.local/lib/python3.6/site-packages/airflow/task/task_runner/standard_task_runner.py", line 86, in _start_by_fork
    args.func(args, dag=self.dag)
[2021-03-04 20:47:42,651] {logging_mixin.py:112} WARNING -   File "/home/airflow/.local/lib/python3.6/site-packages/airflow/utils/cli.py", line 76, in wrapper
    return f(*args, **kwargs)
[2021-03-04 20:47:42,652] {logging_mixin.py:112} WARNING -   File "/home/airflow/.local/lib/python3.6/site-packages/airflow/bin/cli.py", line 579, in run
    _run(args, dag, ti)
[2021-03-04 20:47:42,653] {logging_mixin.py:112} WARNING -   File "/home/airflow/.local/lib/python3.6/site-packages/airflow/bin/cli.py", line 480, in _run
    pool=args.pool,
[2021-03-04 20:47:42,654] {logging_mixin.py:112} WARNING -   File "/home/airflow/.local/lib/python3.6/site-packages/airflow/utils/db.py", line 74, in wrapper
    return func(*args, **kwargs)
[2021-03-04 20:47:42,655] {logging_mixin.py:112} WARNING -   File "/home/airflow/.local/lib/python3.6/site-packages/airflow/models/taskinstance.py", line 984, in _run_raw_task
    result = task_copy.execute(context=context)
[2021-03-04 20:47:42,657] {logging_mixin.py:112} WARNING -   File "/home/airflow/.local/lib/python3.6/site-packages/airflow/operators/python_operator.py", line 113, in execute
    return_value = self.execute_callable()
[2021-03-04 20:47:42,657] {logging_mixin.py:112} WARNING -   File "/home/airflow/.local/lib/python3.6/site-packages/airflow/operators/python_operator.py", line 118, in execute_callable
    return self.python_callable(*self.op_args, **self.op_kwargs)
[2021-03-04 20:47:42,658] {logging_mixin.py:112} WARNING -   File "/opt/airflow/dags/data_clean.py", line 122, in clean_data_df
    logging.info('****** NOAH just dropped the column', print(df.shape))
[2021-03-04 20:47:42,659] {logging_mixin.py:112} WARNING -   File "/usr/local/lib/python3.6/logging/__init__.py", line 1902, in info
    root.info(msg, *args, **kwargs)
[2021-03-04 20:47:42,660] {logging_mixin.py:112} WARNING -   File "/usr/local/lib/python3.6/logging/__init__.py", line 1308, in info
    self._log(INFO, msg, args, **kwargs)
[2021-03-04 20:47:42,661] {logging_mixin.py:112} WARNING -   File "/usr/local/lib/python3.6/logging/__init__.py", line 1444, in _log
    self.handle(record)
[2021-03-04 20:47:42,662] {logging_mixin.py:112} WARNING -   File "/usr/local/lib/python3.6/logging/__init__.py", line 1454, in handle
    self.callHandlers(record)
[2021-03-04 20:47:42,663] {logging_mixin.py:112} WARNING -   File "/usr/local/lib/python3.6/logging/__init__.py", line 1516, in callHandlers
    hdlr.handle(record)
[2021-03-04 20:47:42,664] {logging_mixin.py:112} WARNING -   File "/usr/local/lib/python3.6/logging/__init__.py", line 865, in handle
    self.emit(record)
[2021-03-04 20:47:42,665] {logging_mixin.py:112} WARNING -   File "/home/airflow/.local/lib/python3.6/site-packages/airflow/utils/log/file_task_handler.py", line 63, in emit
    self.handler.emit(record)
[2021-03-04 20:47:42,666] {logging_mixin.py:112} WARNING - Message: '****** NOAH just dropped the column'
Arguments: (None,)
[2021-03-04 20:47:42,669] {logging_mixin.py:112} WARNING - /opt/airflow/dags/data_clean.py:130: SettingWithCopyWarning: 
A value is trying to be set on a copy of a slice from a DataFrame

See the caveats in the documentation: https://pandas.pydata.org/pandas-docs/stable/user_guide/indexing.html#returning-a-view-versus-a-copy
  df['ts'][count] = cleaned
[2021-03-04 20:47:42,673] {taskinstance.py:1150} ERROR - name 'search_request' is not defined
Traceback (most recent call last):
  File "/home/airflow/.local/lib/python3.6/site-packages/airflow/models/taskinstance.py", line 984, in _run_raw_task
    result = task_copy.execute(context=context)
  File "/home/airflow/.local/lib/python3.6/site-packages/airflow/operators/python_operator.py", line 113, in execute
    return_value = self.execute_callable()
  File "/home/airflow/.local/lib/python3.6/site-packages/airflow/operators/python_operator.py", line 118, in execute_callable
    return self.python_callable(*self.op_args, **self.op_kwargs)
  File "/opt/airflow/dags/data_clean.py", line 131, in clean_data_df
    df['ts'] = pd.to_datetime(search_request['ts'], utc=True)
NameError: name 'search_request' is not defined
[2021-03-04 20:47:42,680] {taskinstance.py:1194} INFO - Marking task as UP_FOR_RETRY. dag_id=clean_data, task_id=clean_data_search_result_interaction, execution_date=20210304T204702, start_date=20210304T204742, end_date=20210304T204742
[2021-03-04 20:47:47,138] {local_task_job.py:102} INFO - Task exited with return code 1
